<?xml version="1.0" encoding="utf-8"?>
<!-- This URDF was automatically created by SolidWorks to URDF Exporter! Originally created by Stephen Brawner (brawner@gmail.com) 
     Commit Version: 1.6.0-4-g7f85cfe  Build Version: 1.6.7995.38578
     For more information, please see http://wiki.ros.org/sw_urdf_exporter -->
<robot
  name="new_arm">
  <link
    name="base_link">
    <inertial>
      <origin
        xyz="0.00012027184216136 -0.000110225979837793 0.100099668100807"
        rpy="0 0 0" />
      <mass
        value="0.00137242734628835" />
      <inertia
        ixx="4.93979095549687E-07"
        ixy="-7.18253026975473E-23"
        ixz="2.47584030144931E-23"
        iyy="4.93979095549688E-07"
        iyz="9.07370670625977E-25"
        izz="9.85513400197068E-07" />
    </inertial>
    <visual>
      <origin
        xyz="0 0 0"
        rpy="0 0 0" />
      <geometry>
        <mesh
          filename="package://new_arm/meshes/base_link.STL" />
      </geometry>
      <material
        name="">
        <color
          rgba="1 1 0 1" />
      </material>
    </visual>
    <collision>
      <origin
        xyz="0 0 0"
        rpy="0 0 0" />
      <geometry>
        <mesh
          filename="package://new_arm/meshes/base_link.STL" />
      </geometry>
    </collision>
  </link>
  <link
    name="1_Link">
    <inertial>
      <origin
        xyz="0.000120271842160374 -0.0447893653096206 0.0453999999999996"
        rpy="0 0 0" />
      <mass
        value="0.00131108775038631" />
      <inertia
        ixx="4.84275957119598E-07"
        ixy="1.06491144145097E-22"
        ixz="-3.1887906187469E-23"
        iyy="9.66094911856522E-07"
        iyz="4.44179641532351E-23"
        izz="4.84275957119598E-07" />
    </inertial>
    <visual>
      <origin
        xyz="0 0 0"
        rpy="0 0 0" />
      <geometry>
        <mesh
          filename="package://new_arm/meshes/1_Link.STL" />
      </geometry>
      <material
        name="">
        <color
          rgba="1 0.6 0 1" />
      </material>
    </visual>
    <collision>
      <origin
        xyz="0 0 0"
        rpy="0 0 0" />
      <geometry>
        <mesh
          filename="package://new_arm/meshes/1_Link.STL" />
      </geometry>
    </collision>
  </link>
  <joint
    name="1_join"
    type="revolute">
    <origin
      xyz="0 0 0.1155"
      rpy="0 0 0" />
    <parent
      link="base_link" />
    <child
      link="1_Link" />
    <axis
      xyz="0 0 1" />
    <limit
      lower="-3.05"
      upper="3.05"
      effort="1"
      velocity="0" />
  </joint>
  <link
    name="2_Link">
    <inertial>
      <origin
        xyz="0.000192472426294013 -0.0945429296459426 0.0035344610221747"
        rpy="0 0 0" />
      <mass
        value="0.101643245272993" />
      <inertia
        ixx="0.00054341166795781"
        ixy="-1.21559296393352E-05"
        ixz="1.08666231487326E-07"
        iyy="5.37176770081941E-05"
        iyz="2.15760973431612E-06"
        izz="0.000584569333425057" />
    </inertial>
    <visual>
      <origin
        xyz="0 0 0"
        rpy="0 0 0" />
      <geometry>
        <mesh
          filename="package://new_arm/meshes/2_Link.STL" />
      </geometry>
      <material
        name="">
        <color
          rgba="1 1 0 1" />
      </material>
    </visual>
    <collision>
      <origin
        xyz="0 0 0"
        rpy="0 0 0" />
      <geometry>
        <mesh
          filename="package://new_arm/meshes/2_Link.STL" />
      </geometry>
    </collision>
  </link>
  <joint
    name="2_join"
    type="revolute">
    <origin
      xyz="0.00010086 -0.05551 0.045437"
      rpy="-1.5708 0 0" />
    <parent
      link="1_Link" />
    <child
      link="2_Link" />
    <axis
      xyz="0 0 -1" />
    <limit
      lower="-3.05"
      upper="3.05"
      effort="1"
      velocity="0" />
  </joint>
  <link
    name="3_Link">
    <inertial>
      <origin
        xyz="0.0133258952201139 -0.00410583828256395 0.0232750153646895"
        rpy="0 0 0" />
      <mass
        value="0.000809296258931483" />
      <inertia
        ixx="1.78283138325869E-07"
        ixy="1.07228749406232E-24"
        ixz="3.3247171392602E-24"
        iyy="1.26413626686116E-07"
        iyz="-4.9452068731666E-23"
        izz="2.00721687229904E-07" />
    </inertial>
    <visual>
      <origin
        xyz="0 0 0"
        rpy="0 0 0" />
      <geometry>
        <mesh
          filename="package://new_arm/meshes/3_Link.STL" />
      </geometry>
      <material
        name="">
        <color
          rgba="0.690196078431373 0.690196078431373 0.690196078431373 1" />
      </material>
    </visual>
    <collision>
      <origin
        xyz="0 0 0"
        rpy="0 0 0" />
      <geometry>
        <mesh
          filename="package://new_arm/meshes/3_Link.STL" />
      </geometry>
    </collision>
  </link>
  <joint
    name="3_join"
    type="revolute">
    <origin
      xyz="-0.00010969 -0.20005 0.0185"
      rpy="0 0 0" />
    <parent
      link="2_Link" />
    <child
      link="3_Link" />
    <axis
      xyz="0 0 -1" />
    <limit
      lower="-3.05"
      upper="3.05"
      effort="1"
      velocity="0" />
  </joint>
  <link
    name="4_Link">
    <inertial>
      <origin
        xyz="6.87019915858178E-05 -0.000355824213657143 0.079569974673646"
        rpy="0 0 0" />
      <mass
        value="0.113855209034374" />
      <inertia
        ixx="0.000383167160786053"
        ixy="-3.49590241963328E-07"
        ixz="3.96931495666183E-06"
        iyy="0.000365651820614139"
        iyz="1.23976313155062E-06"
        izz="0.000121865325503606" />
    </inertial>
    <visual>
      <origin
        xyz="0 0 0"
        rpy="0 0 0" />
      <geometry>
        <mesh
          filename="package://new_arm/meshes/4_Link.STL" />
      </geometry>
      <material
        name="">
        <color
          rgba="1 1 0 1" />
      </material>
    </visual>
    <collision>
      <origin
        xyz="0 0 0"
        rpy="0 0 0" />
      <geometry>
        <mesh
          filename="package://new_arm/meshes/4_Link.STL" />
      </geometry>
    </collision>
  </link>
  <joint
    name="4_join"
    type="revolute">
    <origin
      xyz="0.071553 -0.021421 0.042136"
      rpy="-1.5708 0 -1.5708" />
    <parent
      link="3_Link" />
    <child
      link="4_Link" />
    <axis
      xyz="0 0 1" />
    <limit
      lower="-3.05"
      upper="3.05"
      effort="1"
      velocity="0" />
  </joint>
  <link
    name="5_Link">
    <inertial>
      <origin
        xyz="0.0234333615612934 -2.07164631926826E-05 -0.0167505450738613"
        rpy="0 0 0" />
      <mass
        value="0.04488608490997" />
      <inertia
        ixx="1.31426559954384E-05"
        ixy="3.30348990187723E-08"
        ixz="-5.26497717741656E-07"
        iyy="3.06725882559894E-05"
        iyz="1.49766876747997E-09"
        izz="3.37782442895733E-05" />
    </inertial>
    <visual>
      <origin
        xyz="0 0 0"
        rpy="0 0 0" />
      <geometry>
        <mesh
          filename="package://new_arm/meshes/5_Link.STL" />
      </geometry>
      <material
        name="">
        <color
          rgba="0 0 0 1" />
      </material>
    </visual>
    <collision>
      <origin
        xyz="0 0 0"
        rpy="0 0 0" />
      <geometry>
        <mesh
          filename="package://new_arm/meshes/5_Link.STL" />
      </geometry>
    </collision>
  </link>
  <joint
    name="5_join"
    type="revolute">
    <origin
      xyz="-0.00013107 -0.016964 0.14858"
      rpy="-1.5752 -1.5708 3.1416" />
    <parent
      link="4_Link" />
    <child
      link="5_Link" />
    <axis
      xyz="0 0 -1" />
    <limit
      lower="-3.05"
      upper="3.05"
      effort="1"
      velocity="0" />
  </joint>
  <link
    name="6_Link">
    <inertial>
      <origin
        xyz="0.00534355698495642 -0.000117330013118231 0.0202068169966816"
        rpy="0 0 0" />
      <mass
        value="0.0930953314559142" />
      <inertia
        ixx="6.34028894812872E-05"
        ixy="-6.83112393814448E-07"
        ixz="-4.18895930504924E-06"
        iyy="3.13825063977606E-05"
        iyz="-7.33373636380612E-07"
        izz="6.18259321789603E-05" />
    </inertial>
    <visual>
      <origin
        xyz="0 0 0"
        rpy="0 0 0" />
      <geometry>
        <mesh
          filename="package://new_arm/meshes/6_Link.STL" />
      </geometry>
      <material
        name="">
        <color
          rgba="0 0 0 1" />
      </material>
    </visual>
    <collision>
      <origin
        xyz="0 0 0"
        rpy="0 0 0" />
      <geometry>
        <mesh
          filename="package://new_arm/meshes/6_Link.STL" />
      </geometry>
    </collision>
  </link>
  <joint
    name="6_join"
    type="revolute">
    <origin
      xyz="0.05286 -5.5958E-05 -0.016964"
      rpy="-1.5708 0.0044278 -1.5708" />
    <parent
      link="5_Link" />
    <child
      link="6_Link" />
    <axis
      xyz="0 0 1" />
    <limit
      lower="-3.05"
      upper="3.05"
      effort="1"
      velocity="0" />
  </joint>
</robot>